Workbook

Sheet Sheet3

Sheet Distributor_Row_Data
A1: Date | B1: Order_ID | C1: Salesperson | D1: City | E1: Product | F1: Category | G1: Quantity | H1: Sales | I1: Target | J1: Status | K1: Payment_Method | L1: Year | M1: Month_No | N1: Month_Name | O1: Month_Key | P1: Week_Key | Q1: Day_name
A2: 45931 | B2: ORD-10163 | C2: Sneha Iyer | D2: Lucknow | E2: Cola 2L | F2: Beverages | G2: 49 | H2: 2723 | I2: 3100 | J2: Cancelled | K2: Credit | L2: =YEAR($A2) -> 2025 | M2: =MONTH($A2) -> 10 | N2: =TEXT($A2,"mmm") -> Oct | O2: =YEAR($A2)&"-"&TEXT(MONTH($A2),"00") -> 2025-10 | P2: =YEAR($A2)&"-W"&TEXT(WEEKNUM($A2,2),"00") -> 2025-W40 | Q2: =CHOOSE(WEEKDAY($A2,2),"Mon","Tue","Wed","Thu","Fri","Sat","Sun") -> Wed
A3: 45931 | B3: ORD-10825 | C3: Sneha Iyer | D3: Delhi | E3: Potato Chips 100g | F3: Snacks | G3: 10 | H3: 410 | I3: 400 | J3: Delivered | K3: Bank Transfer | L3: =YEAR($A3) -> 2025 | M3: =MONTH($A3) -> 10 | N3: =TEXT($A3,"mmm") -> Oct | O3: =YEAR($A3)&"-"&TEXT(MONTH($A3),"00") -> 2025-10 | P3: =YEAR($A3)&"-W"&TEXT(WEEKNUM($A3,2),"00") -> 2025-W40 | Q3: =CHOOSE(WEEKDAY($A3,2),"Mon","Tue","Wed","Thu","Fri","Sat","Sun") -> Wed
A4: 45932 | B4: ORD-10278 | C4: Arjun Nair | D4: Jaipur | E4: Energy Drink 250ml | F4: Beverages | G4: 49 | H4: 2096 | I4: 2100 | J4: Delivered | K4: Bank Transfer | L4: =YEAR($A4) -> 2025 | M4: =MONTH($A4) -> 10 | N4: =TEXT($A4,"mmm") -> Oct | O4: =YEAR($A4)&"-"&TEXT(MONTH($A4),"00") -> 2025-10 | P4: =YEAR($A4)&"-W"&TEXT(WEEKNUM($A4,2),"00") -> 2025-W40 | Q4: =CHOOSE(WEEKDAY($A4,2),"Mon","Tue","Wed","Thu","Fri","Sat","Sun") -> Thu
A5: 45932 | B5: ORD-10318 | C5: Arjun Nair | D5: Delhi | E5: Namkeen 200g | F5: Snacks | G5: 102 | H5: 3614 | I5: 3200 | J5: Cancelled | K5: Cash | L5: =YEAR($A5) -> 2025 | M5: =MONTH($A5) -> 10 | N5: =TEXT($A5,"mmm") -> Oct | O5: =YEAR($A5)&"-"&TEXT(MONTH($A5),"00") -> 2025-10 | P5: =YEAR($A5)&"-W"&TEXT(WEEKNUM($A5,2),"00") -> 2025-W40 | Q5: =CHOOSE(WEEKDAY($A5,2),"Mon","Tue","Wed","Thu","Fri","Sat","Sun") -> Thu
A6: 45932 | B6: ORD-10664 | C6: Priya Mehta | D6: Delhi | E6: Milk 1L | F6: Dairy | G6: 53 | H6: 2830 | I6: 2700 | J6: Delivered | K6: Cash | L6: =YEAR($A6) -> 2025 | M6: =MONTH($A6) -> 10 | N6: =TEXT($A6,"mmm") -> Oct | O6: =YEAR($A6)&"-"&TEXT(MONTH($A6),"00") -> 2025-10 | P6: =YEAR($A6)&"-W"&TEXT(WEEKNUM($A6,2),"00") -> 2025-W40 | Q6: =CHOOSE(WEEKDAY($A6,2),"Mon","Tue","Wed","Thu","Fri","Sat","Sun") -> Thu
A7: 45932 | B7: ORD-10725 | C7: Priya Mehta | D7: Delhi | E7: Potato Chips 100g | F7: Snacks | G7: 15 | H7: 567 | I7: 500 | J7: Delivered | K7: UPI | L7: =YEAR($A7) -> 2025 | M7: =MONTH($A7) -> 10 | N7: =TEXT($A7,"mmm") -> Oct | O7: =YEAR($A7)&"-"&TEXT(MONTH($A7),"00") -> 2025-10 | P7: =YEAR($A7)&"-W"&TEXT(WEEKNUM($A7,2),"00") -> 2025-W40 | Q7: =CHOOSE(WEEKDAY($A7,2),"Mon","Tue","Wed","Thu","Fri","Sat","Sun") -> Thu
A8: 45932 | B8: ORD-10869 | C8: Amit Verma | D8: Jaipur | E8: Namkeen 200g | F8: Snacks | G8: 47 | H8: 1947 | I8: 2100 | J8: Pending | K8: Cash | L8: =YEAR($A8) -> 2025 | M8: =MONTH($A8) -> 10 | N8: =TEXT($A8,"mmm") -> Oct | O8: =YEAR($A8)&"-"&TEXT(MONTH($A8),"00") -> 2025-10 | P8: =YEAR($A8)&"-W"&TEXT(WEEKNUM($A8,2),"00") -> 2025-W40 | Q8: =CHOOSE(WEEKDAY($A8,2),"Mon","Tue","Wed","Thu","Fri","Sat","Sun") -> Thu
A9: 45933 | B9: ORD-10529 | C9: Amit Verma | D9: Jaipur | E9: Cookies 150g | F9: Snacks | G9: 108 | H9: 4078 | I9: 3600 | J9: Delivered | K9: Cash | L9: =YEAR($A9) -> 2025 | M9: =MONTH($A9) -> 10 | N9: =TEXT($A9,"mmm") -> Oct | O9: =YEAR($A9)&"-"&TEXT(MONTH($A9),"00") -> 2025-10 | P9: =YEAR($A9)&"-W"&TEXT(WEEKNUM($A9,2),"00") -> 2025-W40 | Q9: =CHOOSE(WEEKDAY($A9,2),"Mon","Tue","Wed","Thu","Fri","Sat","Sun") -> Fri
A10: 45933 | B10: ORD-10627 | C10: Rahul Sharma | D10: Delhi | E10: Paneer 200g | F10: Dairy | G10: 78 | H10: 4840 | I10: 5600 | J10: Pending | K10: UPI | L10: =YEAR($A10) -> 2025 | M10: =MONTH($A10) -> 10 | N10: =TEXT($A10,"mmm") -> Oct | O10: =YEAR($A10)&"-"&TEXT(MONTH($A10),"00") -> 2025-10 | P10: =YEAR($A10)&"-W"&TEXT(WEEKNUM($A10,2),"00") -> 2025-W40 | Q10: =CHOOSE(WEEKDAY($A10,2),"Mon","Tue","Wed","Thu","Fri","Sat","Sun") -> Fri
A11: 45935 | B11: ORD-10154 | C11: Amit Verma | D11: Jaipur | E11: Namkeen 200g | F11: Snacks | G11: 79 | H11: 2351 | I11: 2800 | J11: Pending | K11: Cash | L11: =YEAR($A11) -> 2025 | M11: =MONTH($A11) -> 10 | N11: =TEXT($A11,"mmm") -> Oct | O11: =YEAR($A11)&"-"&TEXT(MONTH($A11),"00") -> 2025-10 | P11: =YEAR($A11)&"-W"&TEXT(WEEKNUM($A11,2),"00") -> 2025-W40 | Q11: =CHOOSE(WEEKDAY($A11,2),"Mon","Tue","Wed","Thu","Fri","Sat","Sun") -> Sun
A12: 45936 | B12: ORD-10271 | C12: Priya Mehta | D12: Pune | E12: Orange Juice 1L | F12: Beverages | G12: 72 | H12: 3173 | I12: 3400 | J12: Delivered | K12: UPI | L12: =YEAR($A12) -> 2025 | M12: =MONTH($A12) -> 10 | N12: =TEXT($A12,"mmm") -> Oct | O12: =YEAR($A12)&"-"&TEXT(MONTH($A12),"00") -> 2025-10 | P12: =YEAR($A12)&"-W"&TEXT(WEEKNUM($A12,2),"00") -> 2025-W41 | Q12: =CHOOSE(WEEKDAY($A12,2),"Mon","Tue","Wed","Thu","Fri","Sat","Sun") -> Mon
A13: 45936 | B13: ORD-10489 | C13: Vikram Singh | D13: Delhi | E13: Cola 2L | F13: Beverages | G13: 23 | H13: 1053 | I13: 900 | J13: Delivered | K13: Bank Transfer | L13: =YEAR($A13) -> 2025 | M13: =MONTH($A13) -> 10 | N13: =TEXT($A13,"mmm") -> Oct | O13: =YEAR($A13)&"-"&TEXT(MONTH($A13),"00") -> 2025-10 | P13: =YEAR($A13)&"-W"&TEXT(WEEKNUM($A13,2),"00") -> 2025-W41 | Q13: =CHOOSE(WEEKDAY($A13,2),"Mon","Tue","Wed","Thu","Fri","Sat","Sun") -> Mon
... A901: 46285 | B901: ORD-10409 | C901: Rahul Sharma | D901: Pune | E901: Energy Drink 250ml | F901: Beverages | G901: 36 | H901: 2559 | I901: 2700 | J901: Delivered | K901: Cash | L901: =YEAR($A901) -> 2026 | M901: =MONTH($A901) -> 9 | N901: =TEXT($A901,"mmm") -> Sep | O901: =YEAR($A901)&"-"&TEXT(MONTH($A901),"00") -> 2026-09 | P901: =YEAR($A901)&"-W"&TEXT(WEEKNUM($A901,2),"00") -> 2026-W38 | Q901: =CHOOSE(WEEKDAY($A901,2),"Mon","Tue","Wed","Thu","Fri","Sat","Sun") -> Sun

Sheet Sheet2
B1: 1. DISTRIBUTOR - MIS DASHBOARD
A3: > All figure below are live formulas reading from Distributor_Row_Data. Green cells are yours to edit.
A5: 1. DALY MIS - single-day snapshot
A6: Selected Date - edit this cell | C6: 46252
A7: Total Sales | C7: =SUMIFS(Distributor_Row_Data!H:H,Distributor_Row_Data!A:A,Sheet2!C6) -> 35556
A8: Total Orders | C8: =COUNTIFS(Distributor_Row_Data!A:A,Sheet2!C6) -> 7
A9: Total Taget | C9: =SUMIFS(Distributor_Row_Data!I:I,Distributor_Row_Data!A:A,Sheet2!C6) -> 38000
A10: Achievement % | C10: =IFERROR(C7/C9,0) -> 0.93568421
A11: Pending Orders | C11: =COUNTIFS(Distributor_Row_Data!A:A,Sheet2!C6,Distributor_Row_Data!J:J,"Pending") -> 1
A12: Average Sales per Order | C12: =IFERROR(C7/C8,0) -> 5079.4286
A13: MTD Sales | C13: =SUMIFS(Distributor_Row_Data!H:H,Distributor_Row_Data!A:A,">="&DATE(YEAR(C6),MONTH(C6),1),Distributor_Row_Data!A:A,"<="&Sheet2!C6) -> 186514
A14: YTD Sales | C14: =SUMIFS(Distributor_Row_Data!H:H,Distributor_Row_Data!A:A,">="&DATE(YEAR(C6),1,1),Distributor_Row_Data!A:A,"<="&Sheet2!C6) -> 2265135
A15: Top Salesperson (selected day) | C15: =INDEX(B19:B26,MATCH(MAX(C19:C26),C19:C26,0)) -> Priya Mehta
A17: 2. SALESPERSON PERFORMANCE
B18: Salesperson | C18: Sales (selected day) | D18: Total Sales | E18: Orders | F18: Target | G18: Ach. % | H18: % of Total | I18: Rank
B19: Rahul Sharma | C19: =SUMIFS(Distributor_Row_Data!H:H, Distributor_Row_Data!C:C, $B19, Distributor_Row_Data!A:A,$C$6) -> 2204 | D19: =SUMIFS(Distributor_Row_Data!H:H,Distributor_Row_Data!C:C,Sheet2!$B19) -> 675849 | E19: =COUNTIFS(Distributor_Row_Data!C:C,Sheet2!$B19) -> 176 | F19: =SUMIFS(Distributor_Row_Data!I:I,Distributor_Row_Data!C:C,Sheet2!B19) -> 689500 | G19: =IFERROR($D19/$F19,0) -> 0.9802016 | H19: =IFERROR(D19/SUM(D19:D26),0) -> 0.19765354 | I19: =RANK(D19,$D$19:$D$26) -> 1
B20: Priya Mehta | C20: =SUMIFS(Distributor_Row_Data!H:H, Distributor_Row_Data!C:C, $B20, Distributor_Row_Data!A:A,$C$6) -> 10641 | D20: =SUMIFS(Distributor_Row_Data!H:H,Distributor_Row_Data!C:C,Sheet2!$B20) -> 460439 | E20: =COUNTIFS(Distributor_Row_Data!C:C,Sheet2!$B20) -> 128 | F20: =SUMIFS(Distributor_Row_Data!I:I,Distributor_Row_Data!C:C,Sheet2!B20) -> 472500 | G20: =IFERROR($D20/$F20,0) -> 0.97447407 | H20: =IFERROR(D20/SUM(D20:D27),0) -> 0.16782826 | I20: =RANK(D20,$D$19:$D$26) -> 2
B21: Amit Verma | C21: =SUMIFS(Distributor_Row_Data!H:H, Distributor_Row_Data!C:C, $B21, Distributor_Row_Data!A:A,$C$6) -> 2334 | D21: =SUMIFS(Distributor_Row_Data!H:H,Distributor_Row_Data!C:C,Sheet2!$B21) -> 447328 | E21: =COUNTIFS(Distributor_Row_Data!C:C,Sheet2!$B21) -> 126 | F21: =SUMIFS(Distributor_Row_Data!I:I,Distributor_Row_Data!C:C,Sheet2!B21) -> 456400 | G21: =IFERROR($D21/$F21,0) -> 0.9801227 | H21: =IFERROR(D21/SUM(D21:D28),0) -> 0.19593233 | I21: =RANK(D21,$D$19:$D$26) -> 4
B22: Sneha Iyer | C22: =SUMIFS(Distributor_Row_Data!H:H, Distributor_Row_Data!C:C, $B22, Distributor_Row_Data!A:A,$C$6) -> 6262 | D22: =SUMIFS(Distributor_Row_Data!H:H,Distributor_Row_Data!C:C,Sheet2!$B22) -> 454418 | E22: =COUNTIFS(Distributor_Row_Data!C:C,Sheet2!$B22) -> 123 | F22: =SUMIFS(Distributor_Row_Data!I:I,Distributor_Row_Data!C:C,Sheet2!B22) -> 460000 | G22: =IFERROR($D22/$F22,0) -> 0.98786522 | H22: =IFERROR(D22/SUM(D22:D29),0) -> 0.2475386 | I22: =RANK(D22,$D$19:$D$26) -> 3
B23: Vikram Singh | C23: =SUMIFS(Distributor_Row_Data!H:H, Distributor_Row_Data!C:C, $B23, Distributor_Row_Data!A:A,$C$6) -> 0 | D23: =SUMIFS(Distributor_Row_Data!H:H,Distributor_Row_Data!C:C,Sheet2!$B23) -> 395643 | E23: =COUNTIFS(Distributor_Row_Data!C:C,Sheet2!$B23) -> 107 | F23: =SUMIFS(Distributor_Row_Data!I:I,Distributor_Row_Data!C:C,Sheet2!B23) -> 419300 | G23: =IFERROR($D23/$F23,0) -> 0.94357978 | H23: =IFERROR(D23/SUM(D23:D30),0) -> 0.2864222 | I23: =RANK(D23,$D$19:$D$26) -> 5
B24: Neha Gupta | C24: =SUMIFS(Distributor_Row_Data!H:H, Distributor_Row_Data!C:C, $B24, Distributor_Row_Data!A:A,$C$6) -> 5491 | D24: =SUMIFS(Distributor_Row_Data!H:H,Distributor_Row_Data!C:C,Sheet2!$B24) -> 383663 | E24: =COUNTIFS(Distributor_Row_Data!C:C,Sheet2!$B24) -> 97 | F24: =SUMIFS(Distributor_Row_Data!I:I,Distributor_Row_Data!C:C,Sheet2!B24) -> 385400 | G24: =IFERROR($D24/$F24,0) -> 0.99549299 | H24: =IFERROR(D24/SUM(D24:D31),0) -> 0.38922858 | I24: =RANK(D24,$D$19:$D$26) -> 6
B25: Arjun Nair | C25: =SUMIFS(Distributor_Row_Data!H:H, Distributor_Row_Data!C:C, $B25, Distributor_Row_Data!A:A,$C$6) -> 0 | D25: =SUMIFS(Distributor_Row_Data!H:H,Distributor_Row_Data!C:C,Sheet2!$B25) -> 322748 | E25: =COUNTIFS(Distributor_Row_Data!C:C,Sheet2!$B25) -> 80 | F25: =SUMIFS(Distributor_Row_Data!I:I,Distributor_Row_Data!C:C,Sheet2!B25) -> 324200 | G25: =IFERROR($D25/$F25,0) -> 0.99552128 | H25: =IFERROR(D25/SUM(D25:D32),0) -> 0.53607193 | I25: =RANK(D25,$D$19:$D$26) -> 7
B26: Kavita Rao | C26: =SUMIFS(Distributor_Row_Data!H:H, Distributor_Row_Data!C:C, $B26, Distributor_Row_Data!A:A,$C$6) -> 8624 | D26: =SUMIFS(Distributor_Row_Data!H:H,Distributor_Row_Data!C:C,Sheet2!$B26) -> 279274 | E26: =COUNTIFS(Distributor_Row_Data!C:C,Sheet2!$B26) -> 63 | F26: =SUMIFS(Distributor_Row_Data!I:I,Distributor_Row_Data!C:C,Sheet2!B26) -> 285900 | G26: =IFERROR($D26/$F26,0) -> 0.97682406 | H26: =IFERROR(D26/SUM(D26:D33),0) -> 0.99977447 | I26: =RANK(D26,$D$19:$D$26) -> 8
B29: 3. WEEKLY MIS - last 13 weeks
B30: Week | C30: Sales | D30: Order | E30: Target | F30: Ach. % | G30: WoW Growth %
B31: 2026-W26 | C31: =SUMIFS(Distributor_Row_Data!H:H,Distributor_Row_Data!P:P,Sheet2!B31) -> 70699 | D31: =COUNTIFS(Distributor_Row_Data!P:P,Sheet2!B31) -> 16 | E31: =SUMIFS(Distributor_Row_Data!I:I,Distributor_Row_Data!P:P,Sheet2!B31) -> 71700 | F31: =IFERROR(C31/E31,0) -> 0.98603905 | G31: =IFERROR(C31/C30-1,"")
B32: 2026-W27 | C32: =SUMIFS(Distributor_Row_Data!H:H,Distributor_Row_Data!P:P,Sheet2!B32) -> 103896 | D32: =COUNTIFS(Distributor_Row_Data!P:P,Sheet2!B32) -> 23 | E32: =SUMIFS(Distributor_Row_Data!I:I,Distributor_Row_Data!P:P,Sheet2!B32) -> 113400 | F32: =IFERROR(C32/E32,0) -> 0.91619048 | G32: =IFERROR(C32/C31-1,"") -> 0.46955402
B33: 2026-W28 | C33: =SUMIFS(Distributor_Row_Data!H:H,Distributor_Row_Data!P:P,Sheet2!B33) -> 95090 | D33: =COUNTIFS(Distributor_Row_Data!P:P,Sheet2!B33) -> 24 | E33: =SUMIFS(Distributor_Row_Data!I:I,Distributor_Row_Data!P:P,Sheet2!B33) -> 98300 | F33: =IFERROR(C33/E33,0) -> 0.96734486 | G33: =IFERROR(C33/C32-1,"") -> -0.084757835
B34: 2026-W29 | C34: =SUMIFS(Distributor_Row_Data!H:H,Distributor_Row_Data!P:P,Sheet2!B34) -> 51186 | D34: =COUNTIFS(Distributor_Row_Data!P:P,Sheet2!B34) -> 17 | E34: =SUMIFS(Distributor_Row_Data!I:I,Distributor_Row_Data!P:P,Sheet2!B34) -> 54200 | F34: =IFERROR(C34/E34,0) -> 0.94439114 | G34: =IFERROR(C34/C33-1,"") -> -0.46170996
B35: 2026-W30 | C35: =SUMIFS(Distributor_Row_Data!H:H,Distributor_Row_Data!P:P,Sheet2!B35) -> 59554 | D35: =COUNTIFS(Distributor_Row_Data!P:P,Sheet2!B35) -> 14 | E35: =SUMIFS(Distributor_Row_Data!I:I,Distributor_Row_Data!P:P,Sheet2!B35) -> 59200 | F35: =IFERROR(C35/E35,0) -> 1.0059797 | G35: =IFERROR(C35/C34-1,"") -> 0.1634822
B36: 2026-W31 | C36: =SUMIFS(Distributor_Row_Data!H:H,Distributor_Row_Data!P:P,Sheet2!B36) -> 61566 | D36: =COUNTIFS(Distributor_Row_Data!P:P,Sheet2!B36) -> 19 | E36: =SUMIFS(Distributor_Row_Data!I:I,Distributor_Row_Data!P:P,Sheet2!B36) -> 63200 | F36: =IFERROR(C36/E36,0) -> 0.97414557 | G36: =IFERROR(C36/C35-1,"") -> 0.033784465
B37: 2026-W32 | C37: =SUMIFS(Distributor_Row_Data!H:H,Distributor_Row_Data!P:P,Sheet2!B37) -> 56764 | D37: =COUNTIFS(Distributor_Row_Data!P:P,Sheet2!B37) -> 14 | E37: =SUMIFS(Distributor_Row_Data!I:I,Distributor_Row_Data!P:P,Sheet2!B37) -> 58800 | F37: =IFERROR(C37/E37,0) -> 0.96537415 | G37: =IFERROR(C37/C36-1,"") -> -0.077997596
B38: 2026-W33 | C38: =SUMIFS(Distributor_Row_Data!H:H,Distributor_Row_Data!P:P,Sheet2!B38) -> 71935 | D38: =COUNTIFS(Distributor_Row_Data!P:P,Sheet2!B38) -> 16 | E38: =SUMIFS(Distributor_Row_Data!I:I,Distributor_Row_Data!P:P,Sheet2!B38) -> 77800 | F38: =IFERROR(C38/E38,0) -> 0.9246144 | G38: =IFERROR(C38/C37-1,"") -> 0.26726446
B39: 2026-W34 | C39: =SUMIFS(Distributor_Row_Data!H:H,Distributor_Row_Data!P:P,Sheet2!B39) -> 109742 | D39: =COUNTIFS(Distributor_Row_Data!P:P,Sheet2!B39) -> 23 | E39: =SUMIFS(Distributor_Row_Data!I:I,Distributor_Row_Data!P:P,Sheet2!B39) -> 114500 | F39: =IFERROR(C39/E39,0) -> 0.95844541 | G39: =IFERROR(C39/C38-1,"") -> 0.5255717
B40: 2026-W35 | C40: =SUMIFS(Distributor_Row_Data!H:H,Distributor_Row_Data!P:P,Sheet2!B40) -> 22330 | D40: =COUNTIFS(Distributor_Row_Data!P:P,Sheet2!B40) -> 7 | E40: =SUMIFS(Distributor_Row_Data!I:I,Distributor_Row_Data!P:P,Sheet2!B40) -> 20100 | F40: =IFERROR(C40/E40,0) -> 1.1109453 | G40: =IFERROR(C40/C39-1,"") -> -0.79652275
B41: 2026-W36 | C41: =SUMIFS(Distributor_Row_Data!H:H,Distributor_Row_Data!P:P,Sheet2!B41) -> 62306 | D41: =COUNTIFS(Distributor_Row_Data!P:P,Sheet2!B41) -> 18 | E41: =SUMIFS(Distributor_Row_Data!I:I,Distributor_Row_Data!P:P,Sheet2!B41) -> 64600 | F41: =IFERROR(C41/E41,0) -> 0.96448916 | G41: =IFERROR(C41/C40-1,"") -> 1.7902373
B42: 2026-W37 | C42: =SUMIFS(Distributor_Row_Data!H:H,Distributor_Row_Data!P:P,Sheet2!B42) -> 65273 | D42: =COUNTIFS(Distributor_Row_Data!P:P,Sheet2!B42) -> 15 | E42: =SUMIFS(Distributor_Row_Data!I:I,Distributor_Row_Data!P:P,Sheet2!B42) -> 65600 | F42: =IFERROR(C42/E42,0) -> 0.99501524 | G42: =IFERROR(C42/C41-1,"") -> 0.047619812
B43: 2026-W38 | C43: =SUMIFS(Distributor_Row_Data!H:H,Distributor_Row_Data!P:P,Sheet2!B43) -> 83572 | D43: =COUNTIFS(Distributor_Row_Data!P:P,Sheet2!B43) -> 21 | E43: =SUMIFS(Distributor_Row_Data!I:I,Distributor_Row_Data!P:P,Sheet2!B43) -> 88300 | F43: =IFERROR(C43/E43,0) -> 0.94645527 | G43: =IFERROR(C43/C42-1,"") -> 0.28034563
B46: 4. MONTHLY MIS - revenue, MoM, YTD
B47: Month | C47: Sales | D47: Orders | E47: Target | F47: Ach. % | G47: MoM Growth % | H47: YTD
...
